I'm sorry, but an uncaught exception occurred.

While running game code:
  File "game/script.rpy", line 73, in script
    $ you = Person(0, "Your name")
  File "game/script.rpy", line 73, in <module>
    $ you = Person(0, "Your name")
  File "game/init_python.rpy", line 18, in __init__
    self.z = None
  File "game/init_python.rpy", line 81, in z
    raise ValueError
ValueError: 

-- Full Traceback ------------------------------------------------------------

Full traceback:
  File "game/script.rpy", line 73, in script
    $ you = Person(0, "Your name")
  File "/Applications/renpy-8.1.3-sdk/renpy/ast.py", line 823, in execute
    renpy.python.py_exec_bytecode(self.code.bytecode, self.hide, store=self.store)
  File "/Applications/renpy-8.1.3-sdk/renpy/python.py", line 1178, in py_exec_bytecode
    exec(bytecode, globals, locals)
  File "game/script.rpy", line 73, in <module>
    $ you = Person(0, "Your name")
  File "game/init_python.rpy", line 18, in __init__
    self.z = None
  File "/Applications/renpy-8.1.3-sdk/renpy/revertable.py", line 97, in do_mutation
    return method(self, *args, **kwargs)
  File "game/init_python.rpy", line 81, in z
    raise ValueError
ValueError: 

macOS-14.4.1-arm64-arm-64bit arm64
Ren'Py 8.2.3.24061702
Wizard Demo Game 1.0
Sat Oct 12 18:50:42 2024
